<?xml version="1.0"?>
<robot name="cafebot">

  <!-- ==================== MATERIALS ==================== -->
  <material name="black">
    <color rgba="0.0 0.0 0.0 1.0"/>
  </material>

  <material name="dark_grey">
    <color rgba="0.3 0.3 0.3 1.0"/>
  </material>

  <material name="grey">
    <color rgba="0.7 0.7 0.7 1.0"/>
  </material>

  <material name="white">
    <color rgba="1.0 1.0 1.0 1.0"/>
  </material>

  <material name="blue">
    <color rgba="0.0 0.0 0.8 1.0"/>
  </material>

  <material name="red">
    <color rgba="0.8 0.0 0.0 1.0"/>
  </material>

  <!-- ==================== BASE LINK ==================== -->
  <link name="base_footprint"/>

  <link name="base_link">
    <visual>
      <geometry>
        <box size="0.5 0.5 0.15"/>
      </geometry>
      <material name="dark_grey"/>
      <origin xyz="0 0 0.075"/>
    </visual>
    <collision>
      <geometry>
        <box size="0.5 0.5 0.15"/>
      </geometry>
      <origin xyz="0 0 0.075"/>
    </collision>
    <inertial>
      <mass value="5.0"/>
      <origin xyz="0 0 0.075"/>
      <inertia ixx="0.1" ixy="0" ixz="0" iyy="0.1" iyz="0" izz="0.1"/>
    </inertial>
  </link>

  <joint name="base_joint" type="fixed">
    <parent link="base_footprint"/>
    <child link="base_link"/>
    <origin xyz="0 0 0.0"/>
  </joint>

  <!-- ==================== WHEELS ==================== -->
  <!-- Left Wheel -->
  <link name="left_wheel">
    <visual>
      <geometry>
        <cylinder radius="0.08" length="0.04"/>
      </geometry>
      <material name="black"/>
      <origin rpy="1.5707 0 0" xyz="0 0 0"/>
    </visual>
    <collision>
      <geometry>
        <cylinder radius="0.08" length="0.04"/>
      </geometry>
      <origin rpy="1.5707 0 0" xyz="0 0 0"/>
    </collision>
    <inertial>
      <mass value="1.0"/>
      <origin rpy="1.5707 0 0" xyz="0 0 0"/>
      <inertia ixx="0.003" ixy="0" ixz="0" iyy="0.003" iyz="0" izz="0.003"/>
    </inertial>
  </link>

  <joint name="left_wheel_joint" type="continuous">
    <parent link="base_link"/>
    <child link="left_wheel"/>
    <origin xyz="0 0.275 0.08"/>
    <axis xyz="0 1 0"/>
  </joint>

  <!-- Right Wheel -->
  <link name="right_wheel">
    <visual>
      <geometry>
        <cylinder radius="0.08" length="0.04"/>
      </geometry>
      <material name="black"/>
      <origin rpy="1.5707 0 0" xyz="0 0 0"/>
    </visual>
    <collision>
      <geometry>
        <cylinder radius="0.08" length="0.04"/>
      </geometry>
      <origin rpy="1.5707 0 0" xyz="0 0 0"/>
    </collision>
    <inertial>
      <mass value="1.0"/>
      <origin rpy="1.5707 0 0" xyz="0 0 0"/>
      <inertia ixx="0.003" ixy="0" ixz="0" iyy="0.003" iyz="0" izz="0.003"/>
    </inertial>
  </link>

  <joint name="right_wheel_joint" type="continuous">
    <parent link="base_link"/>
    <child link="right_wheel"/>
    <origin xyz="0 -0.275 0.08"/>
    <axis xyz="0 1 0"/>
  </joint>

  <!-- ==================== CASTER WHEELS ==================== -->
  <!-- Front Caster -->
  <link name="front_caster">
    <visual>
      <geometry>
        <sphere radius="0.05"/>
      </geometry>
      <material name="black"/>
    </visual>
    <collision>
      <geometry>
        <sphere radius="0.05"/>
      </geometry>
    </collision>
    <inertial>
      <mass value="0.5"/>
      <inertia ixx="0.0005" ixy="0" ixz="0" iyy="0.0005" iyz="0" izz="0.0005"/>
    </inertial>
  </link>

  <joint name="front_caster_joint" type="fixed">
    <parent link="base_link"/>
    <child link="front_caster"/>
    <origin xyz="0.2 0 0.05"/>
  </joint>

  <!-- Rear Caster -->
  <link name="rear_caster">
    <visual>
      <geometry>
        <sphere radius="0.05"/>
      </geometry>
      <material name="black"/>
    </visual>
    <collision>
      <geometry>
        <sphere radius="0.05"/>
      </geometry>
    </collision>
    <inertial>
      <mass value="0.5"/>
      <inertia ixx="0.0005" ixy="0" ixz="0" iyy="0.0005" iyz="0" izz="0.0005"/>
    </inertial>
  </link>

  <joint name="rear_caster_joint" type="fixed">
    <parent link="base_link"/>
    <child link="rear_caster"/>
    <origin xyz="-0.2 0 0.05"/>
  </joint>

  <!-- ==================== COMPARTMENTS ==================== -->
  <!-- Main Body Column -->
  <link name="body_column">
    <visual>
      <geometry>
        <box size="0.4 0.4 0.8"/>
      </geometry>
      <material name="grey"/>
      <origin xyz="0 0 0.4"/>
    </visual>
    <collision>
      <geometry>
        <box size="0.4 0.4 0.8"/>
      </geometry>
      <origin xyz="0 0 0.4"/>
    </collision>
    <inertial>
      <mass value="3.0"/>
      <origin xyz="0 0 0.4"/>
      <inertia ixx="0.2" ixy="0" ixz="0" iyy="0.2" iyz="0" izz="0.1"/>
    </inertial>
  </link>

  <joint name="body_column_joint" type="fixed">
    <parent link="base_link"/>
    <child link="body_column"/>
    <origin xyz="0 0 0.15"/>
  </joint>

  <!-- Bottom Compartment -->
  <link name="compartment_1">
    <visual>
      <geometry>
        <box size="0.35 0.35 0.20"/>
      </geometry>
      <material name="white"/>
      <origin xyz="0 0 0"/>
    </visual>
    <collision>
      <geometry>
        <box size="0.35 0.35 0.20"/>
      </geometry>
      <origin xyz="0 0 0"/>
    </collision>
    <inertial>
      <mass value="0.5"/>
      <origin xyz="0 0 0"/>
      <inertia ixx="0.01" ixy="0" ixz="0" iyy="0.01" iyz="0" izz="0.01"/>
    </inertial>
  </link>

  <joint name="compartment_1_joint" type="fixed">
    <parent link="body_column"/>
    <child link="compartment_1"/>
    <origin xyz="0 0 0.15"/>
  </joint>

  <!-- Middle Compartment -->
  <link name="compartment_2">
    <visual>
      <geometry>
        <box size="0.35 0.35 0.20"/>
      </geometry>
      <material name="white"/>
      <origin xyz="0 0 0"/>
    </visual>
    <collision>
      <geometry>
        <box size="0.35 0.35 0.20"/>
      </geometry>
      <origin xyz="0 0 0"/>
    </collision>
    <inertial>
      <mass value="0.5"/>
      <origin xyz="0 0 0"/>
      <inertia ixx="0.01" ixy="0" ixz="0" iyy="0.01" iyz="0" izz="0.01"/>
    </inertial>
  </link>

  <joint name="compartment_2_joint" type="fixed">
    <parent link="body_column"/>
    <child link="compartment_2"/>
    <origin xyz="0 0 0.4"/>
  </joint>

  <!-- Top Compartment -->
  <link name="compartment_3">
    <visual>
      <geometry>
        <box size="0.35 0.35 0.20"/>
      </geometry>
      <material name="white"/>
      <origin xyz="0 0 0"/>
    </visual>
    <collision>
      <geometry>
        <box size="0.35 0.35 0.20"/>
      </geometry>
      <origin xyz="0 0 0"/>
    </collision>
    <inertial>
      <mass value="0.5"/>
      <origin xyz="0 0 0"/>
      <inertia ixx="0.01" ixy="0" ixz="0" iyy="0.01" iyz="0" izz="0.01"/>
    </inertial>
  </link>

  <joint name="compartment_3_joint" type="fixed">
    <parent link="body_column"/>
    <child link="compartment_3"/>
    <origin xyz="0 0 0.65"/>
  </joint>

  <!-- ==================== SENSORS ==================== -->
  <!-- LiDAR -->
  <link name="lidar_link">
    <visual>
      <geometry>
        <cylinder radius="0.05" length="0.05"/>
      </geometry>
      <material name="black"/>
      <origin xyz="0 0 0"/>
    </visual>
    <collision>
      <geometry>
        <cylinder radius="0.05" length="0.05"/>
      </geometry>
      <origin xyz="0 0 0"/>
    </collision>
    <inertial>
      <mass value="0.1"/>
      <origin xyz="0 0 0"/>
      <inertia ixx="0.0001" ixy="0" ixz="0" iyy="0.0001" iyz="0" izz="0.0001"/>
    </inertial>
  </link>

  <joint name="lidar_joint" type="fixed">
    <parent link="body_column"/>
    <child link="lidar_link"/>
    <origin xyz="0 0 0.85"/>
  </joint>

  <!-- IMU -->
  <link name="imu_link">
    <visual>
      <geometry>
        <box size="0.05 0.05 0.02"/>
      </geometry>
      <material name="blue"/>
      <origin xyz="0 0 0"/>
    </visual>
    <collision>
      <geometry>
        <box size="0.05 0.05 0.02"/>
      </geometry>
      <origin xyz="0 0 0"/>
    </collision>
    <inertial>
      <mass value="0.01"/>
      <origin xyz="0 0 0"/>
      <inertia ixx="0.00001" ixy="0" ixz="0" iyy="0.00001" iyz="0" izz="0.00001"/>
    </inertial>
  </link>

  <joint name="imu_joint" type="fixed">
    <parent link="base_link"/>
    <child link="imu_link"/>
    <origin xyz="0 0 0.15"/>
  </joint>

  <!-- Front Camera -->
  <link name="camera_link">
    <visual>
      <geometry>
        <box size="0.05 0.1 0.05"/>
      </geometry>
      <material name="red"/>
      <origin xyz="0 0 0"/>
    </visual>
    <collision>
      <geometry>
        <box size="0.05 0.1 0.05"/>
      </geometry>
      <origin xyz="0 0 0"/>
    </collision>
    <inertial>
      <mass value="0.05"/>
      <origin xyz="0 0 0"/>
      <inertia ixx="0.00001" ixy="0" ixz="0" iyy="0.00001" iyz="0" izz="0.00001"/>
    </inertial>
  </link>

  <joint name="camera_joint" type="fixed">
    <parent link="body_column"/>
    <child link="camera_link"/>
    <origin xyz="0.2 0 0.85"/>
  </joint>

  <!-- ==================== GAZEBO PLUGINS ==================== -->
  <!-- Differential Drive Controller -->
  <gazebo>
    <plugin name='diff_drive' filename='libgazebo_ros_diff_drive.so'>
      <ros>
        <!-- <namespace>/cafebot</namespace> -->
      </ros>
      <!-- wheels -->
      <left_joint>left_wheel_joint</left_joint>
      <right_joint>right_wheel_joint</right_joint>
      <!-- kinematics -->
      <wheel_separation>0.545</wheel_separation>
      <wheel_diameter>0.16</wheel_diameter>
      <!-- limits -->
      <max_wheel_torque>100</max_wheel_torque>
      <max_wheel_acceleration>2.0</max_wheel_acceleration>
      <!-- output -->
      <publish_odom>true</publish_odom>
      <publish_odom_tf>true</publish_odom_tf>
      <publish_wheel_tf>true</publish_wheel_tf>
      <odometry_frame>odom</odometry_frame>
      <robot_base_frame>base_link</robot_base_frame>
    </plugin>
  </gazebo>

  <!-- Joint State Publisher -->
  <gazebo>
    <plugin name="joint_state_publisher" filename="libgazebo_ros_joint_state_publisher.so">
      <ros>
        <namespace>/</namespace>
      </ros>
      <update_rate>50</update_rate>
      <joint_name>left_wheel_joint</joint_name>
      <joint_name>right_wheel_joint</joint_name>
    </plugin>
  </gazebo>

  <!-- LiDAR Sensor -->
  <gazebo reference="lidar_link">
    <sensor name="lidar" type="ray">
      <always_on>true</always_on>
      <visualize>false</visualize>
      <update_rate>10</update_rate>
      <ray>
        <scan>
          <horizontal>
            <samples>360</samples>
            <resolution>1.000000</resolution>
            <min_angle>-3.14</min_angle>
            <max_angle>3.14</max_angle>
          </horizontal>
        </scan>
        <range>
          <min>0.10</min>
          <max>10.0</max>
          <resolution>0.01</resolution>
        </range>
        <noise>
          <type>gaussian</type>
          <mean>0.0</mean>
          <stddev>0.01</stddev>
        </noise>
      </ray>
      <plugin name="scan" filename="libgazebo_ros_ray_sensor.so">
        <ros>
          <remapping>~/out:=scan</remapping>
        </ros>
        <output_type>sensor_msgs/LaserScan</output_type>
        <frame_name>lidar_link</frame_name>
      </plugin>
    </sensor>
  </gazebo>

  <!-- IMU Sensor -->
  <gazebo reference="imu_link">
    <sensor type="imu" name="imu">
      <always_on>true</always_on>
      <update_rate>100</update_rate>
      <visualize>true</visualize>
      <plugin name="imu_plugin" filename="libgazebo_ros_imu_sensor.so">
        <ros>
          <remapping>~/out:=imu</remapping>
        </ros>
        <initial_orientation_as_reference>false</initial_orientation_as_reference>
      </plugin>
    </sensor>
  </gazebo>

  <!-- Camera Sensor -->
  <gazebo reference="camera_link">
    <sensor type="camera" name="camera">
      <update_rate>30.0</update_rate>
      <camera name="head">
        <horizontal_fov>1.3962634</horizontal_fov>
        <image>
          <width>640</width>
          <height>480</height>
          <format>R8G8B8</format>
        </image>
        <clip>
          <near>0.02</near>
          <far>300</far>
        </clip>
        <noise>
          <type>gaussian</type>
          <mean>0.0</mean>
          <stddev>0.007</stddev>
        </noise>
      </camera>
      <plugin name="camera_controller" filename="libgazebo_ros_camera.so">
        <ros>
          <namespace>/cafebot</namespace>
        </ros>
        <frame_name>camera_link</frame_name>
      </plugin>
    </sensor>
  </gazebo>

  <!-- Physics Properties -->
  <gazebo reference="base_link">
    <mu1>0.5</mu1>
    <mu2>0.5</mu2>
    <selfCollide>true</selfCollide>
    <gravity>true</gravity>
  </gazebo>

  <gazebo reference="left_wheel">
    <mu1>40.0</mu1>
    <mu2>40.0</mu2>
    <selfCollide>true</selfCollide>
  </gazebo>

  <gazebo reference="right_wheel">
    <mu1>40.0</mu1>
    <mu2>40.0</mu2>
    <selfCollide>true</selfCollide>
  </gazebo>

  <gazebo reference="front_caster">
    <mu1>0.1</mu1>
    <mu2>0.1</mu2>
    <selfCollide>true</selfCollide>
  </gazebo>

  <gazebo reference="rear_caster">
    <mu1>0.1</mu1>
    <mu2>0.1</mu2>
    <selfCollide>true</selfCollide>
  </gazebo>

  <!-- Material Colors for Gazebo -->
  <gazebo reference="base_link">
    <material>Gazebo/DarkGrey</material>
  </gazebo>

  <gazebo reference="body_column">
    <material>Gazebo/Grey</material>
  </gazebo>

  <gazebo reference="compartment_1">
    <material>Gazebo/White</material>
  </gazebo>

  <gazebo reference="compartment_2">
    <material>Gazebo/White</material>
  </gazebo>

  <gazebo reference="compartment_3">
    <material>Gazebo/White</material>
  </gazebo>

  <gazebo reference="lidar_link">
    <material>Gazebo/Black</material>
  </gazebo>

  <gazebo reference="left_wheel">
    <material>Gazebo/Black</material>
  </gazebo>

  <gazebo reference="right_wheel">
    <material>Gazebo/Black</material>
  </gazebo>

</robot>